Workbook
Name SPEC_LOW: 'Index & Checks'!$B$5
Name SPEC_HIGH: 'Index & Checks'!$B$6

Sheet Index & Checks
A1: ASIAN LAKTO INDUSTRIES LTD – QC RECORDS, AUGUST 2026
A2: Five photographed paper forms, transcribed and verified. One sheet per source document.
A4: Acceptance band for cap-removal torque (editable)
A5: Lower limit (lb-in) | B5: 8
A6: Upper limit (lb-in) | B6: 19
A7: The torque form prints no specification limits. These two figures were derived from the source itself: across both torque sheets the chemist ringed 19 readings as rejected and left 39 un-ringed. Every un-ringed reading falls in 9.6–18.5 lb-in and every ringed one falls outside 7.9–20.0, so the true limits must lie between those bounds. 8.0 and 19.0 sit inside that gap. Replace them with the plant's actual specification and every check in the workbook re-derives.
A11: Sheets in this workbook
A12: Sheet | B12: Source photo | C12: Report | D12: Date | E12: Chemist | F12: Shift | G12: Product | H12: Data captured
A13: CSD 17-08-2026 | B13: Photo 3 (PDF page 3) | C13: CSD PET ONLINE RECORD | D13: 17/08/26 | E13: Pammee Singh | F13: Day | G13: MC2 Original 250 ml | H13: ='CSD 17-08-2026'!AB29&" cell entries"
A14: CSD 19-08-2026 | B14: Photo 5 (PDF page 5) | C14: CSD PET ONLINE RECORD | D14: 19/08/26 | E14: Aafreen | F14: Day | G14: MC2 Original 250 ml | H14: ='CSD 19-08-2026'!AB29&" cell entries"
A15: CSD 20-08-2026 | B15: Photo 1 (PDF page 1) | C15: CSD PET ONLINE RECORD | D15: 20/08/26 | E15: Pammee Singh | F15: Day | G15: MC2 Original 250 ml | H15: ='CSD 20-08-2026'!AB29&" cell entries"
A16: Torque 17-08-2026 | B16: Photo 4 (PDF page 4) | C16: TORQUE TESTING REPORT (HYMECH LINE) | D16: 17/08/26 | E16: Pammee | F16: Day | G16: MC2 Original 250 ml (cap make MD) | H16: ='Torque 17-08-2026'!$B$37&" torque readings"
A17: Torque 20-08-2026 | B17: Photo 2 (PDF page 2) | C17: TORQUE TESTING REPORT (HYMECH LINE) | D17: 20/08/26 | E17: Pammee Singh | F17: Day | G17: MC2 Original 250 ml (cap make MD) | H17: ='Torque 20-08-2026'!$B$37&" torque readings"
A19: Live verification roll-up
A20: Check | C20: Result | D20: Expected
A21: Numeric torque readings transcribed | C21: ='Torque 17-08-2026'!$B$37+'Torque 20-08-2026'!$B$37 | D21: 58
A22: Entries the chemist ringed as rejected | C22: ='Torque 17-08-2026'!R26+'Torque 17-08-2026'!R29+'Torque 20-08-2026'!R26+'Torque 20-08-2026'!R29 | D22: 21 = 19 numeric readings + 2 'No open' entries
A23: Numeric readings the band formula flags as out of spec | C23: ='Torque 17-08-2026'!R27+'Torque 17-08-2026'!R30+'Torque 20-08-2026'!R27+'Torque 20-08-2026'!R30 | D23: 19 – must equal the ringed numeric readings
A24: Band test disagrees with the chemist's ringing | C24: ='Torque 17-08-2026'!R28+'Torque 17-08-2026'!R31+'Torque 20-08-2026'!R28+'Torque 20-08-2026'!R31 | D24: 0 – any other value means a digit was misread
A25: CSD :00/:30 reading pairs written on the forms | C25: ='CSD 17-08-2026'!AG29+'CSD 19-08-2026'!AG29+'CSD 20-08-2026'!AG29 | D25: 102
A26: CSD pairs whose two halves differ | C26: ='CSD 17-08-2026'!AH29+'CSD 19-08-2026'!AH29+'CSD 20-08-2026'!AH29 | D26: 2 – both are source anomalies, flagged with comments
A28: Flags, ambiguities and source anomalies
A29: Sheet | B29: Where | C29: Kind | D29: What we found and what we did
A30: Torque 20-08-2026 | B30: 11:00, head 6 | C30: Source gap | D30: 7.9 lb-in is ringed as rejected but no re-test was written underneath, unlike every other ringed reading on either sheet. The head's outcome is unrecorded on the form; the cell is left empty here rather than filled in.
A31: CSD 20-08-2026 | B31: Temperature, 12:00 | C31: Source anomaly / verify | D31: Reads 6.1 °C. Legible, but it breaks the :00/:30 pairing used throughout the sheet (12:30 reads 10.1) and is far below every other temperature logged that day. Reproduced as written.
A32: CSD 17-08-2026 | B32: Temperature, 02:30 | C32: Source anomaly / verify | D32: Reads 12.8 °C against 12.2 °C at 02:00 – the only unequal pair on the sheet. Both digits are clear; reproduced rather than harmonised.
A33: Torque 20-08-2026 | B33: 01:00, head 11 | C33: Ambiguous digits | D33: Read as 20.0; the last character is over-written and could be 20.6. Ringed as rejected either way and re-tested at 11.5, so the outcome is unaffected.
A34: Torque 20-08-2026 | B34: 01:00, head 6 | C34: Ambiguous digit | D34: Read as 13.2; the final digit could be 6. Both values are inside the band, so the OK result is unaffected.
A35: Torque 17-08-2026 | B35: 11:00, head 10 | C35: Ambiguous digit | D35: Read as 6.0; the leading digit is written over itself and 0 is conceivable. Ringed and re-tested at 10.8 either way.
A36: Torque 17-08-2026 | B36: 01:00, head 13 | C36: Partially overlapped | D36: Read as 25.1; the last digit sits on the cell boundary and is crossed by the ring drawn around head 14.
A37: Torque 17-08-2026 / 20-08-2026 | B37: 11:00, heads 14 and 7 | C37: Non-numeric entry | D37: 'No open' written instead of a reading (the cap would not release), with 'open' written above the cell. Re-tests of 16.0 and 16.6 lb-in were recorded. Kept as text; the statistics count numeric readings only.
A38: CSD 17-08-2026 and 20-08-2026 | B38: 'As is brix' and '% Acidity' rows | C38: Source gap | D38: Both rows are entirely blank although the form requires brix every 30 minutes and acidity every hour. The 19-08 sheet has them filled. Left blank here.
A39: CSD 20-08-2026 | B39: Note below the table | C39: Cut off in the photograph | D39: The handwritten note ends '...time 7:00 Pm start' and the final line runs off the bottom edge of the photograph. Transcribed as far as it is visible.
A40: CSD 17-08-2026 | B40: Filler start annotation | C40: Uncertain word | D40: Read as 'Filler Start 8:38 AM'. The verb is written indistinctly; 'Start' is supported by readings beginning at 09:00 and by the same phrase on the 19-08 sheet.
... A43: Both torque sheets | B43: Acceptance limits | C43: Not printed on the form | D43: The band used by the checks was inferred from the chemist's own ringing – see the top of this sheet. It is not a figure taken from the document.
A45: How this workbook was produced
A46: • Five photographs were extracted from the supplied PDF at their embedded resolution (no re-rendering) and checked for EXIF rotation; none needed rotating.
A47: • The photographs group into two report families: three dated CSD PET Online Record sheets (17, 19 and 20 August) and two dated Torque Testing Report sheets (17 and 20 August). No photograph is a continuation page of another, so each gets its own sheet.
A48: • Column and row rulings were detected computationally in each photograph, then every data cell was cut out individually and read at high magnification, so no value depends on judging which column a digit belongs to by eye.
A49: • Neither form carries an arithmetic column to check against, so two structural checks were used instead: on the torque sheets, whether a single acceptance band separates the readings the chemist ringed from the ones he did not (58 of 58 agree); on the CSD sheets, whether the :00 and :30 halves of each logged pair match (100 of 102 do, and both exceptions are listed above).
...

Sheet CSD 17-08-2026
A1: CSD PET ONLINE RECORD
A2: Doc No.: CSD-PET-FRM-03 | transcribed from Photo 3 (PDF page 3)
A4: Date | B4: 17/08/26 | E4: Finished Syrup B.No. | J4: (blank on form)
A5: Product | B5: MC2 Original 250 ml | E5: Control Drink As is Brix | J5: (blank on form)
A6: Chemist | B6: Pammee Singh | E6: Control Drink Invert Brix | J6: (blank on form)
A7: Shift | B7: Day | E7: Control Drink % Acidity | J7: (blank on form)
A9: Parameter | B9: Frequency | C9: 08:00 | D9: 08:30 | E9: 09:00 | F9: 09:30 | G9: 10:00 | H9: 10:30 | I9: 11:00 | J9: 11:30 | K9: 12:00 | L9: 12:30 | M9: 01:00 | N9: 01:30 | O9: 02:00 | P9: 02:30 | Q9: 03:00 | R9: 03:30 | S9: 04:00 | T9: 04:30 | U9: 05:00 | V9: 05:30 | W9: 06:00 | X9: 06:30 | Y9: 07:00 | Z9: 07:30 | AA9: 08:00 | AB9: Entries | AC9: OK count | AD9: Min | AE9: Max | AF9: Average | AG9: :00/:30 pairs | AH9: Pairs differing
A10: 24-hour equivalent → | C10: 08:00 | D10: 08:30 | E10: 09:00 | F10: 09:30 | G10: 10:00 | H10: 10:30 | I10: 11:00 | J10: 11:30 | K10: 12:00 | L10: 12:30 | M10: 13:00 | N10: 13:30 | O10: 14:00 | P10: 14:30 | Q10: 15:00 | R10: 15:30 | S10: 16:00 | T10: 16:30 | U10: 17:00 | V10: 17:30 | W10: 18:00 | X10: 18:30 | Y10: 19:00 | Z10: 19:30 | AA10: 20:00
A11: As is brix (Bev.) | B11: Startup & Every 30 Min | AB11: =COUNT($C11:$AA11) | AD11: =IF(COUNT($C11:$AA11)=0,"",MIN($C11:$AA11)) | AE11: =IF(COUNT($C11:$AA11)=0,"",MAX($C11:$AA11)) | AF11: =IF(COUNT($C11:$AA11)=0,"",AVERAGE($C11:$AA11)) | AG11: =SUMPRODUCT((MOD(COLUMN($C11:$Z11)-COLUMN($C$1),2)=0)*($C11:$Z11<>"")*($D11:$AA11<>"")) | AH11: =SUMPRODUCT((MOD(COLUMN($C11:$Z11)-COLUMN($C$1),2)=0)*($C11:$Z11<>"")*($D11:$AA11<>"")*($C11:$Z11<>$D11:$AA11))
A12: % Acidity | B12: startup & Every hrs | AB12: =COUNT($C12:$AA12) | AD12: =IF(COUNT($C12:$AA12)=0,"",MIN($C12:$AA12)) | AE12: =IF(COUNT($C12:$AA12)=0,"",MAX($C12:$AA12)) | AF12: =IF(COUNT($C12:$AA12)=0,"",AVERAGE($C12:$AA12)) | AG12: =SUMPRODUCT((MOD(COLUMN($C12:$Z12)-COLUMN($C$1),2)=0)*($C12:$Z12<>"")*($D12:$AA12<>"")) | AH12: =SUMPRODUCT((MOD(COLUMN($C12:$Z12)-COLUMN($C$1),2)=0)*($C12:$Z12<>"")*($D12:$AA12<>"")*($C12:$Z12<>$D12:$AA12))
A13: Pressure | B13: Startup & Every 30 Min | E13: 36 | F13: 36 | G13: 40 | H13: 40 | I13: 40 | J13: 40 | K13: 44 | L13: 44 | M13: 42 | N13: 42 | O13: 46 | P13: 46 | Q13: 44 | R13: 44 | S13: 44 | T13: 44 | U13: 46 | V13: 46 | Y13: 46 | Z13: 46 | AB13: =COUNT($C13:$AA13) | AD13: =IF(COUNT($C13:$AA13)=0,"",MIN($C13:$AA13)) | AE13: =IF(COUNT($C13:$AA13)=0,"",MAX($C13:$AA13)) | AF13: =IF(COUNT($C13:$AA13)=0,"",AVERAGE($C13:$AA13)) | AG13: =SUMPRODUCT((MOD(COLUMN($C13:$Z13)-COLUMN($C$1),2)=0)*($C13:$Z13<>"")*($D13:$AA13<>"")) | AH13: =SUMPRODUCT((MOD(COLUMN($C13:$Z13)-COLUMN($C$1),2)=0)*($C13:$Z13<>"")*($D13:$AA13<>"")*($C13:$Z13<>$D13:$AA13))
A14: Temperature | B14: Startup & Every 30 Min | E14: 10.4 | F14: 10.4 | G14: 13.4 | H14: 13.4 | I14: 11.7 | J14: 11.7 | K14: 14 | L14: 14 | M14: 10.6 | N14: 10.6 | O14: 12.2 | P14: 12.8 | Q14: 14.6 | R14: 14.6 | S14: 13.7 | T14: 13.7 | U14: 15.1 | V14: 15.1 | Y14: 15.2 | Z14: 15.2 | AB14: =COUNT($C14:$AA14) | AD14: =IF(COUNT($C14:$AA14)=0,"",MIN($C14:$AA14)) | AE14: =IF(COUNT($C14:$AA14)=0,"",MAX($C14:$AA14)) | AF14: =IF(COUNT($C14:$AA14)=0,"",AVERAGE($C14:$AA14)) | AG14: =SUMPRODUCT((MOD(COLUMN($C14:$Z14)-COLUMN($C$1),2)=0)*($C14:$Z14<>"")*($D14:$AA14<>"")) | AH14: =SUMPRODUCT((MOD(COLUMN($C14:$Z14)-COLUMN($C$1),2)=0)*($C14:$Z14<>"")*($D14:$AA14<>"")*($C14:$Z14<>$D14:$AA14))
A15: G.V. | B15: Startup & Every 30 Min | E15: 3.9 | F15: 3.9 | G15: 3.9 | H15: 3.9 | I15: 4.1 | J15: 4.1 | K15: 4.1 | L15: 4.1 | M15: 4.4 | N15: 4.4 | O15: 4.4 | P15: 4.4 | Q15: 4.1 | R15: 4.1 | S15: 4.2 | T15: 4.2 | U15: 4.1 | V15: 4.1 | Y15: 4.1 | Z15: 4.1 | AB15: =COUNT($C15:$AA15) | AD15: =IF(COUNT($C15:$AA15)=0,"",MIN($C15:$AA15)) | AE15: =IF(COUNT($C15:$AA15)=0,"",MAX($C15:$AA15)) | AF15: =IF(COUNT($C15:$AA15)=0,"",AVERAGE($C15:$AA15)) | AG15: =SUMPRODUCT((MOD(COLUMN($C15:$Z15)-COLUMN($C$1),2)=0)*($C15:$Z15<>"")*($D15:$AA15<>"")) | AH15: =SUMPRODUCT((MOD(COLUMN($C15:$Z15)-COLUMN($C$1),2)=0)*($C15:$Z15<>"")*($D15:$AA15<>"")*($C15:$Z15<>$D15:$AA15))
A16: TOA | B16: Startup & Every 30 Min | E16: OK | F16: OK | G16: OK | H16: OK | I16: OK | J16: OK | K16: OK | L16: OK | M16: OK | N16: OK | O16: OK | P16: OK | Q16: OK | R16: OK | S16: OK | T16: OK | U16: OK | V16: OK | Y16: OK | Z16: OK | AB16: =COUNTA($C16:$AA16) | AC16: =COUNTIF($C16:$AA16,"OK")
A17: Stress Crack Test | B17: Start Up & Every 4 Hours | E17: OK | F17: OK | G17: OK | H17: OK | I17: OK | J17: OK | K17: OK | L17: OK | M17: OK | N17: OK | O17: OK | P17: OK | Q17: OK | R17: OK | S17: OK | T17: OK | U17: OK | V17: OK | Y17: OK | Z17: OK | AB17: =COUNTA($C17:$AA17) | AC17: =COUNTIF($C17:$AA17,"OK")
A18: Candling (observation) | B18: Every 2 hrs. | E18: – | F18: – | G18: – | H18: – | I18: – | J18: – | K18: – | L18: – | M18: – | N18: – | O18: – | P18: – | Q18: – | R18: – | S18: – | T18: – | U18: – | V18: – | Y18: – | Z18: – | AB18: =COUNTA($C18:$AA18) | AC18: =COUNTIF($C18:$AA18,"OK")
A19: Beverage Temprature After Warmer | B19: Startup & 4 hrs | E19: – | F19: – | G19: – | H19: – | I19: – | J19: – | K19: – | L19: – | M19: – | N19: – | O19: – | P19: – | Q19: – | R19: – | S19: – | T19: – | U19: – | V19: – | Y19: – | Z19: – | AB19: =COUNTA($C19:$AA19) | AC19: =COUNTIF($C19:$AA19,"OK")
A20: Condensation on Bottle | B20: Startup & 2 hrs | E20: – | F20: – | G20: – | H20: – | I20: – | J20: – | K20: – | L20: – | M20: – | N20: – | O20: – | P20: – | Q20: – | R20: – | S20: – | T20: – | U20: – | V20: – | Y20: – | Z20: – | AB20: =COUNTA($C20:$AA20) | AC20: =COUNTIF($C20:$AA20,"OK")
A21: Label Alignment | B21: Startup & Every 30 Min | E21: OK | F21: OK | G21: OK | H21: OK | I21: OK | J21: OK | K21: OK | L21: OK | M21: OK | N21: OK | O21: OK | P21: OK | Q21: OK | R21: OK | S21: OK | T21: OK | U21: OK | V21: OK | Y21: OK | Z21: OK | AB21: =COUNTA($C21:$AA21) | AC21: =COUNTIF($C21:$AA21,"OK")
A22: Glue Application | B22: Startup & Every 30 Min | E22: OK | F22: OK | G22: OK | H22: OK | I22: OK | J22: OK | K22: OK | L22: OK | M22: OK | N22: OK | O22: OK | P22: OK | Q22: OK | R22: OK | S22: OK | T22: OK | U22: OK | V22: OK | Y22: OK | Z22: OK | AB22: =COUNTA($C22:$AA22) | AC22: =COUNTIF($C22:$AA22,"OK")
A23: Primary Coding | B23: Startup & Every 30 Min | E23: OK | F23: OK | G23: OK | H23: OK | I23: OK | J23: OK | K23: OK | L23: OK | M23: OK | N23: OK | O23: OK | P23: OK | Q23: OK | R23: OK | S23: OK | T23: OK | U23: OK | V23: OK | Y23: OK | Z23: OK | AB23: =COUNTA($C23:$AA23) | AC23: =COUNTIF($C23:$AA23,"OK")
A24: Shrink packing Quality | B24: Startup & Every Hour | E24: OK | F24: OK | G24: OK | H24: OK | I24: OK | J24: OK | K24: OK | L24: OK | M24: OK | N24: OK | O24: OK | P24: OK | Q24: OK | R24: OK | S24: OK | T24: OK | U24: OK | V24: OK | Y24: OK | Z24: OK | AB24: =COUNTA($C24:$AA24) | AC24: =COUNTIF($C24:$AA24,"OK")
A25: Torque | B25: All Capper Heads Start Up & Every 2 Hours | AB25: =COUNTA($C25:$AA25) | AC25: =COUNTIF($C25:$AA25,"OK")
A26: Closure Lot No. | AB26: =COUNTA($C26:$AA26) | AC26: =COUNTIF($C26:$AA26,"OK")
A27: Label Lot No. | AB27: =COUNTA($C27:$AA27) | AC27: =COUNTIF($C27:$AA27,"OK")
A28: Preform Lot No. | AB28: =COUNTA($C28:$AA28) | AC28: =COUNTIF($C28:$AA28,"OK")
A29: Parameters filled in this column | B29: (live count) | C29: =COUNTA(C11:C28) | D29: =COUNTA(D11:D28) | E29: =COUNTA(E11:E28) | F29: =COUNTA(F11:F28) | G29: =COUNTA(G11:G28) | H29: =COUNTA(H11:H28) | I29: =COUNTA(I11:I28) | J29: =COUNTA(J11:J28) | ... AA29: =COUNTA(AA11:AA28) | AB29: =SUM(C29:AA29) | AG29: =SUM(AG11:AG28) | AH29: =SUM(AH11:AH28)
A31: Annotations written on the form
A32: Where | B32: What the chemist wrote
A33: Time column, spanning the sheet | B33: Vertical note: "Filler Start 8:38 AM", with arrows spanning the full column height.
A35: Remark (as written on form) | B35: (left blank on the form)
A36: QC Chemist | B36: Pammee Singh | E36: QC Manager | I36: (initialled)
A38: Notes on this sheet
A39: • Blank cell = left blank on the paper form. – = a dash was written (the test was not due at that interval). OK = written as OK.
A40: • The 24-hour row under the printed times is our addition; the form prints 12-hour times with no am/pm marker.
A41: • Entries / OK count / Min / Max / Average / pair columns are live formulas over the time columns to their left - correct any reading and they re-derive.
A42: • “:00/:30 pairs” counts the paired readings actually written; “Pairs differing” counts pairs whose two halves are not identical. That is the accuracy check for this form, which carries no arithmetic column.
A43: • Cells carrying a red figure have a comment attached explaining the ambiguity or source anomaly.
A44: • FLAGGED - Temperature at 02:30: The only :00/:30 pair on this sheet whose two halves differ. Both digits are clearly legible; reproduced as printed rather than harmonised. Worth a check against the original.

Sheet CSD 19-08-2026
A1: CSD PET ONLINE RECORD
A2: Doc No.: CSD-PET-FRM-03 | transcribed from Photo 5 (PDF page 5)
A4: Date | B4: 19/08/26 | E4: Finished Syrup B.No. | J4: (blank on form)
A5: Product | B5: MC2 Original 250 ml | E5: Control Drink As is Brix | J5: (blank on form)
A6: Chemist | B6: Aafreen | E6: Control Drink Invert Brix | J6: (blank on form)
A7: Shift | B7: Day | E7: Control Drink % Acidity | J7: (blank on form)
A9: Parameter | B9: Frequency | C9: 08:00 | D9: 08:30 | E9: 09:00 | F9: 09:30 | G9: 10:00 | H9: 10:30 | I9: 11:00 | J9: 11:30 | K9: 12:00 | L9: 12:30 | M9: 01:00 | N9: 01:30 | O9: 02:00 | P9: 02:30 | Q9: 03:00 | R9: 03:30 | S9: 04:00 | T9: 04:30 | U9: 05:00 | V9: 05:30 | W9: 06:00 | X9: 06:30 | Y9: 07:00 | Z9: 07:30 | AA9: 08:00 | AB9: Entries | AC9: OK count | AD9: Min | AE9: Max | AF9: Average | AG9: :00/:30 pairs | AH9: Pairs differing
A10: 24-hour equivalent → | C10: 08:00 | D10: 08:30 | E10: 09:00 | F10: 09:30 | G10: 10:00 | H10: 10:30 | I10: 11:00 | J10: 11:30 | K10: 12:00 | L10: 12:30 | M10: 13:00 | N10: 13:30 | O10: 14:00 | P10: 14:30 | Q10: 15:00 | R10: 15:30 | S10: 16:00 | T10: 16:30 | U10: 17:00 | V10: 17:30 | W10: 18:00 | X10: 18:30 | Y10: 19:00 | Z10: 19:30 | AA10: 20:00
A11: As is brix (Bev.) | B11: Startup & Every 30 Min | E11: 10.96 | F11: 10.96 | G11: 11.18 | H11: 11.18 | K11: 11.07 | L11: 11.07 | O11: 11.12 | P11: 11.12 | Q11: 11.02 | R11: 11.02 | S11: 11.17 | T11: 11.17 | U11: 11.03 | V11: 11.03 | W11: 10.92 | X11: 10.92 | Y11: 10.98 | Z11: 10.98 | AB11: =COUNT($C11:$AA11) | AD11: =IF(COUNT($C11:$AA11)=0,"",MIN($C11:$AA11)) | AE11: =IF(COUNT($C11:$AA11)=0,"",MAX($C11:$AA11)) | AF11: =IF(COUNT($C11:$AA11)=0,"",AVERAGE($C11:$AA11)) | AG11: =SUMPRODUCT((MOD(COLUMN($C11:$Z11)-COLUMN($C$1),2)=0)*($C11:$Z11<>"")*($D11:$AA11<>"")) | AH11: =SUMPRODUCT((MOD(COLUMN($C11:$Z11)-COLUMN($C$1),2)=0)*($C11:$Z11<>"")*($D11:$AA11<>"")*($C11:$Z11<>$D11:$AA11))
A12: % Acidity | B12: startup & Every hrs | E12: 0.7 | F12: 0.7 | G12: 0.7 | H12: 0.7 | K12: 0.7 | L12: 0.7 | O12: 0.68 | P12: 0.68 | Q12: 0.7 | R12: 0.7 | S12: 0.7 | T12: 0.7 | U12: 0.7 | V12: 0.7 | W12: 0.7 | X12: 0.7 | Y12: 0.7 | Z12: 0.7 | AB12: =COUNT($C12:$AA12) | AD12: =IF(COUNT($C12:$AA12)=0,"",MIN($C12:$AA12)) | AE12: =IF(COUNT($C12:$AA12)=0,"",MAX($C12:$AA12)) | AF12: =IF(COUNT($C12:$AA12)=0,"",AVERAGE($C12:$AA12)) | AG12: =SUMPRODUCT((MOD(COLUMN($C12:$Z12)-COLUMN($C$1),2)=0)*($C12:$Z12<>"")*($D12:$AA12<>"")) | AH12: =SUMPRODUCT((MOD(COLUMN($C12:$Z12)-COLUMN($C$1),2)=0)*($C12:$Z12<>"")*($D12:$AA12<>"")*($C12:$Z12<>$D12:$AA12))
A13: Pressure | B13: Startup & Every 30 Min | E13: 42 | F13: 42 | G13: 43 | H13: 43 | K13: 48 | L13: 48 | O13: 38 | P13: 38 | Q13: 40 | R13: 40 | S13: 44 | T13: 44 | U13: 46 | V13: 46 | W13: 42 | X13: 42 | Y13: 40 | Z13: 40 | AB13: =COUNT($C13:$AA13) | AD13: =IF(COUNT($C13:$AA13)=0,"",MIN($C13:$AA13)) | AE13: =IF(COUNT($C13:$AA13)=0,"",MAX($C13:$AA13)) | AF13: =IF(COUNT($C13:$AA13)=0,"",AVERAGE($C13:$AA13)) | AG13: =SUMPRODUCT((MOD(COLUMN($C13:$Z13)-COLUMN($C$1),2)=0)*($C13:$Z13<>"")*($D13:$AA13<>"")) | AH13: =SUMPRODUCT((MOD(COLUMN($C13:$Z13)-COLUMN($C$1),2)=0)*($C13:$Z13<>"")*($D13:$AA13<>"")*($C13:$Z13<>$D13:$AA13))
A14: Temperature | B14: Startup & Every 30 Min | E14: 10.2 | F14: 10.2 | G14: 9.5 | H14: 9.5 | K14: 14.2 | L14: 14.2 | O14: 10.3 | P14: 10.3 | Q14: 13 | R14: 13 | S14: 13.8 | T14: 13.8 | U14: 13.8 | V14: 13.8 | W14: 9.5 | X14: 9.5 | Y14: 10.3 | Z14: 10.3 | AB14: =COUNT($C14:$AA14) | AD14: =IF(COUNT($C14:$AA14)=0,"",MIN($C14:$AA14)) | AE14: =IF(COUNT($C14:$AA14)=0,"",MAX($C14:$AA14)) | AF14: =IF(COUNT($C14:$AA14)=0,"",AVERAGE($C14:$AA14)) | AG14: =SUMPRODUCT((MOD(COLUMN($C14:$Z14)-COLUMN($C$1),2)=0)*($C14:$Z14<>"")*($D14:$AA14<>"")) | AH14: =SUMPRODUCT((MOD(COLUMN($C14:$Z14)-COLUMN($C$1),2)=0)*($C14:$Z14<>"")*($D14:$AA14<>"")*($C14:$Z14<>$D14:$AA14))
A15: G.V. | B15: Startup & Every 30 Min | E15: 4.4 | F15: 4.4 | G15: 4.6 | H15: 4.6 | K15: 4.4 | L15: 4.4 | O15: 4.2 | P15: 4.2 | Q15: 4 | R15: 4 | S15: 4.2 | T15: 4.2 | U15: 4.3 | V15: 4.3 | W15: 4.6 | X15: 4.6 | Y15: 4.3 | Z15: 4.3 | AB15: =COUNT($C15:$AA15) | AD15: =IF(COUNT($C15:$AA15)=0,"",MIN($C15:$AA15)) | AE15: =IF(COUNT($C15:$AA15)=0,"",MAX($C15:$AA15)) | AF15: =IF(COUNT($C15:$AA15)=0,"",AVERAGE($C15:$AA15)) | AG15: =SUMPRODUCT((MOD(COLUMN($C15:$Z15)-COLUMN($C$1),2)=0)*($C15:$Z15<>"")*($D15:$AA15<>"")) | AH15: =SUMPRODUCT((MOD(COLUMN($C15:$Z15)-COLUMN($C$1),2)=0)*($C15:$Z15<>"")*($D15:$AA15<>"")*($C15:$Z15<>$D15:$AA15))
A16: TOA | B16: Startup & Every 30 Min | E16: OK | F16: OK | G16: OK | H16: OK | K16: OK | L16: OK | O16: OK | P16: OK | Q16: OK | R16: OK | S16: OK | T16: OK | U16: OK | V16: OK | W16: OK | X16: OK | Y16: OK | Z16: OK | AB16: =COUNTA($C16:$AA16) | AC16: =COUNTIF($C16:$AA16,"OK")
A17: Stress Crack Test | B17: Start Up & Every 4 Hours | E17: OK | F17: – | G17: – | H17: – | K17: – | L17: – | O17: – | P17: – | Q17: – | R17: – | S17: – | T17: – | U17: – | V17: – | W17: – | X17: – | Y17: – | Z17: – | AB17: =COUNTA($C17:$AA17) | AC17: =COUNTIF($C17:$AA17,"OK")
A18: Candling (observation) | B18: Every 2 hrs. | E18: – | F18: – | G18: – | H18: – | K18: – | L18: – | O18: – | P18: – | Q18: – | R18: – | S18: – | T18: – | U18: – | V18: – | W18: – | X18: – | Y18: – | Z18: – | AB18: =COUNTA($C18:$AA18) | AC18: =COUNTIF($C18:$AA18,"OK")
A19: Beverage Temprature After Warmer | B19: Startup & 4 hrs | E19: – | F19: – | G19: – | H19: – | K19: – | L19: – | O19: – | P19: – | Q19: – | R19: – | S19: – | T19: – | U19: – | V19: – | W19: – | X19: – | Y19: – | Z19: – | AB19: =COUNTA($C19:$AA19) | AC19: =COUNTIF($C19:$AA19,"OK")
A20: Condensation on Bottle | B20: Startup & 2 hrs | E20: – | F20: – | G20: – | H20: – | K20: – | L20: – | O20: – | P20: – | Q20: – | R20: – | S20: – | T20: – | U20: – | V20: – | W20: – | X20: – | Y20: – | Z20: – | AB20: =COUNTA($C20:$AA20) | AC20: =COUNTIF($C20:$AA20,"OK")
A21: Label Alignment | B21: Startup & Every 30 Min | E21: OK | F21: OK | G21: OK | H21: OK | K21: OK | L21: OK | O21: OK | P21: OK | Q21: OK | R21: OK | S21: OK | T21: OK | U21: OK | V21: OK | W21: OK | X21: OK | Y21: OK | Z21: OK | AB21: =COUNTA($C21:$AA21) | AC21: =COUNTIF($C21:$AA21,"OK")
A22: Glue Application | B22: Startup & Every 30 Min | E22: OK | F22: OK | G22: OK | H22: OK | K22: OK | L22: OK | O22: OK | P22: OK | Q22: OK | R22: OK | S22: OK | T22: OK | U22: OK | V22: OK | W22: OK | X22: OK | Y22: OK | Z22: OK | AB22: =COUNTA($C22:$AA22) | AC22: =COUNTIF($C22:$AA22,"OK")
A23: Primary Coding | B23: Startup & Every 30 Min | E23: OK | F23: OK | G23: OK | H23: OK | K23: OK | L23: OK | O23: OK | P23: OK | Q23: OK | R23: OK | S23: OK | T23: OK | U23: OK | V23: OK | W23: OK | X23: OK | Y23: OK | Z23: OK | AB23: =COUNTA($C23:$AA23) | AC23: =COUNTIF($C23:$AA23,"OK")
A24: Shrink packing Quality | B24: Startup & Every Hour | E24: OK | F24: OK | G24: OK | H24: OK | K24: OK | L24: OK | O24: OK | P24: OK | Q24: OK | R24: OK | S24: OK | T24: OK | U24: OK | V24: OK | W24: OK | X24: OK | Y24: OK | Z24: OK | AB24: =COUNTA($C24:$AA24) | AC24: =COUNTIF($C24:$AA24,"OK")
A25: Torque | B25: All Capper Heads Start Up & Every 2 Hours | E25: OK | F25: – | G25: – | H25: – | K25: – | L25: – | O25: – | P25: – | Q25: – | R25: – | S25: – | T25: – | U25: – | V25: – | W25: – | X25: – | Y25: – | Z25: – | AB25: =COUNTA($C25:$AA25) | AC25: =COUNTIF($C25:$AA25,"OK")
A26: Closure Lot No. | AB26: =COUNTA($C26:$AA26) | AC26: =COUNTIF($C26:$AA26,"OK")
A27: Label Lot No. | AB27: =COUNTA($C27:$AA27) | AC27: =COUNTIF($C27:$AA27,"OK")
A28: Preform Lot No. | AB28: =COUNTA($C28:$AA28) | AC28: =COUNTIF($C28:$AA28,"OK")
A29: Parameters filled in this column | B29: (live count) | C29: =COUNTA(C11:C28) | D29: =COUNTA(D11:D28) | E29: =COUNTA(E11:E28) | F29: =COUNTA(F11:F28) | G29: =COUNTA(G11:G28) | H29: =COUNTA(H11:H28) | I29: =COUNTA(I11:I28) | J29: =COUNTA(J11:J28) | ... AA29: =COUNTA(AA11:AA28) | AB29: =SUM(C29:AA29) | AG29: =SUM(AG11:AG28) | AH29: =SUM(AH11:AH28)
A31: Annotations written on the form
A32: Where | B32: What the chemist wrote
A33: 08:30 column | B33: Vertical note: "Filler Start 8:30 am" with an arrow.
A34: 11:00 - 11:30 columns | B34: Vertical note: "Filler stop due to outfeed knife setting & welding work" - no readings logged for these two intervals.
A35: 01:00 - 01:30 columns | B35: Vertical note: "Line stop" with arrows - no readings logged.
A36: 08:00 PM column | B36: Vertical note: "shift over".
A38: Remark (as written on form) | B38: (left blank on the form)
A39: QC Chemist | B39: Aafreen | E39: QC Manager | I39: (initialled)
A41: Notes on this sheet
A42: • Blank cell = left blank on the paper form. – = a dash was written (the test was not due at that interval). OK = written as OK.
A43: • The 24-hour row under the printed times is our addition; the form prints 12-hour times with no am/pm marker.
A44: • Entries / OK count / Min / Max / Average / pair columns are live formulas over the time columns to their left - correct any reading and they re-derive.
A45: • “:00/:30 pairs” counts the paired readings actually written; “Pairs differing” counts pairs whose two halves are not identical. That is the accuracy check for this form, which carries no arithmetic column.
...

Sheet CSD 20-08-2026
A1: CSD PET ONLINE RECORD
A2: Doc No.: CSD-PET-FRM-03 | transcribed from Photo 1 (PDF page 1)
A4: Date | B4: 20/08/26 | E4: Finished Syrup B.No. | J4: (blank on form)
A5: Product | B5: MC2 Original 250 ml | E5: Control Drink As is Brix | J5: (blank on form)
A6: Chemist | B6: Pammee Singh | E6: Control Drink Invert Brix | J6: (blank on form)
A7: Shift | B7: Day | E7: Control Drink % Acidity | J7: (blank on form)
A9: Parameter | B9: Frequency | C9: 08:00 | D9: 08:30 | E9: 09:00 | F9: 09:30 | G9: 10:00 | H9: 10:30 | I9: 11:00 | J9: 11:30 | K9: 12:00 | L9: 12:30 | M9: 01:00 | N9: 01:30 | O9: 02:00 | P9: 02:30 | Q9: 03:00 | R9: 03:30 | S9: 04:00 | T9: 04:30 | U9: 05:00 | V9: 05:30 | W9: 06:00 | X9: 06:30 | Y9: 07:00 | Z9: 07:30 | AA9: 08:00 | AB9: Entries | AC9: OK count | AD9: Min | AE9: Max | AF9: Average | AG9: :00/:30 pairs | AH9: Pairs differing
A10: 24-hour equivalent → | C10: 08:00 | D10: 08:30 | E10: 09:00 | F10: 09:30 | G10: 10:00 | H10: 10:30 | I10: 11:00 | J10: 11:30 | K10: 12:00 | L10: 12:30 | M10: 13:00 | N10: 13:30 | O10: 14:00 | P10: 14:30 | Q10: 15:00 | R10: 15:30 | S10: 16:00 | T10: 16:30 | U10: 17:00 | V10: 17:30 | W10: 18:00 | X10: 18:30 | Y10: 19:00 | Z10: 19:30 | AA10: 20:00
A11: As is brix (Bev.) | B11: Startup & Every 30 Min | AB11: =COUNT($C11:$AA11) | AD11: =IF(COUNT($C11:$AA11)=0,"",MIN($C11:$AA11)) | AE11: =IF(COUNT($C11:$AA11)=0,"",MAX($C11:$AA11)) | AF11: =IF(COUNT($C11:$AA11)=0,"",AVERAGE($C11:$AA11)) | AG11: =SUMPRODUCT((MOD(COLUMN($C11:$Z11)-COLUMN($C$1),2)=0)*($C11:$Z11<>"")*($D11:$AA11<>"")) | AH11: =SUMPRODUCT((MOD(COLUMN($C11:$Z11)-COLUMN($C$1),2)=0)*($C11:$Z11<>"")*($D11:$AA11<>"")*($C11:$Z11<>$D11:$AA11))
A12: % Acidity | B12: startup & Every hrs | AB12: =COUNT($C12:$AA12) | AD12: =IF(COUNT($C12:$AA12)=0,"",MIN($C12:$AA12)) | AE12: =IF(COUNT($C12:$AA12)=0,"",MAX($C12:$AA12)) | AF12: =IF(COUNT($C12:$AA12)=0,"",AVERAGE($C12:$AA12)) | AG12: =SUMPRODUCT((MOD(COLUMN($C12:$Z12)-COLUMN($C$1),2)=0)*($C12:$Z12<>"")*($D12:$AA12<>"")) | AH12: =SUMPRODUCT((MOD(COLUMN($C12:$Z12)-COLUMN($C$1),2)=0)*($C12:$Z12<>"")*($D12:$AA12<>"")*($C12:$Z12<>$D12:$AA12))
A13: Pressure | B13: Startup & Every 30 Min | C13: 40 | D13: 40 | E13: 36 | F13: 36 | I13: 42 | J13: 42 | K13: 40 | L13: 40 | M13: 40 | N13: 40 | O13: 38 | P13: 38 | Q13: 40 | R13: 40 | S13: 38 | T13: 38 | Y13: 42 | Z13: 42 | AB13: =COUNT($C13:$AA13) | AD13: =IF(COUNT($C13:$AA13)=0,"",MIN($C13:$AA13)) | AE13: =IF(COUNT($C13:$AA13)=0,"",MAX($C13:$AA13)) | AF13: =IF(COUNT($C13:$AA13)=0,"",AVERAGE($C13:$AA13)) | AG13: =SUMPRODUCT((MOD(COLUMN($C13:$Z13)-COLUMN($C$1),2)=0)*($C13:$Z13<>"")*($D13:$AA13<>"")) | AH13: =SUMPRODUCT((MOD(COLUMN($C13:$Z13)-COLUMN($C$1),2)=0)*($C13:$Z13<>"")*($D13:$AA13<>"")*($C13:$Z13<>$D13:$AA13))
A14: Temperature | B14: Startup & Every 30 Min | C14: 8.5 | D14: 8.5 | E14: 8.5 | F14: 8.5 | I14: 8.7 | J14: 8.7 | K14: 6.1 | L14: 10.1 | M14: 7.4 | N14: 7.4 | O14: 10.2 | P14: 10.2 | Q14: 9.3 | R14: 9.3 | S14: 10 | T14: 10 | Y14: 13.1 | Z14: 13.1 | AB14: =COUNT($C14:$AA14) | AD14: =IF(COUNT($C14:$AA14)=0,"",MIN($C14:$AA14)) | AE14: =IF(COUNT($C14:$AA14)=0,"",MAX($C14:$AA14)) | AF14: =IF(COUNT($C14:$AA14)=0,"",AVERAGE($C14:$AA14)) | AG14: =SUMPRODUCT((MOD(COLUMN($C14:$Z14)-COLUMN($C$1),2)=0)*($C14:$Z14<>"")*($D14:$AA14<>"")) | AH14: =SUMPRODUCT((MOD(COLUMN($C14:$Z14)-COLUMN($C$1),2)=0)*($C14:$Z14<>"")*($D14:$AA14<>"")*($C14:$Z14<>$D14:$AA14))
A15: G.V. | B15: Startup & Every 30 Min | C15: 4.5 | D15: 4.5 | E15: 4.2 | F15: 4.2 | I15: 4.7 | J15: 4.7 | K15: 4.3 | L15: 4.3 | M15: 4.7 | N15: 4.7 | O15: 4.1 | P15: 4.1 | Q15: 4.4 | R15: 4.4 | S15: 4.2 | T15: 4.2 | Y15: 4.1 | Z15: 4.1 | AB15: =COUNT($C15:$AA15) | AD15: =IF(COUNT($C15:$AA15)=0,"",MIN($C15:$AA15)) | AE15: =IF(COUNT($C15:$AA15)=0,"",MAX($C15:$AA15)) | AF15: =IF(COUNT($C15:$AA15)=0,"",AVERAGE($C15:$AA15)) | AG15: =SUMPRODUCT((MOD(COLUMN($C15:$Z15)-COLUMN($C$1),2)=0)*($C15:$Z15<>"")*($D15:$AA15<>"")) | AH15: =SUMPRODUCT((MOD(COLUMN($C15:$Z15)-COLUMN($C$1),2)=0)*($C15:$Z15<>"")*($D15:$AA15<>"")*($C15:$Z15<>$D15:$AA15))
A16: TOA | B16: Startup & Every 30 Min | C16: OK | D16: OK | E16: OK | F16: OK | I16: OK | J16: OK | K16: OK | L16: OK | M16: OK | N16: OK | O16: OK | P16: OK | Q16: OK | R16: OK | S16: OK | T16: OK | Y16: OK | Z16: OK | AB16: =COUNTA($C16:$AA16) | AC16: =COUNTIF($C16:$AA16,"OK")
A17: Stress Crack Test | B17: Start Up & Every 4 Hours | C17: OK | D17: OK | E17: OK | F17: OK | I17: OK | J17: OK | K17: OK | L17: OK | M17: OK | N17: OK | O17: OK | P17: OK | Q17: OK | R17: OK | S17: OK | T17: OK | Y17: OK | Z17: OK | AB17: =COUNTA($C17:$AA17) | AC17: =COUNTIF($C17:$AA17,"OK")
A18: Candling (observation) | B18: Every 2 hrs. | C18: – | D18: – | E18: – | F18: – | I18: – | J18: – | K18: – | L18: – | M18: – | N18: – | O18: – | P18: – | Q18: – | R18: – | S18: – | T18: – | Y18: – | Z18: – | AB18: =COUNTA($C18:$AA18) | AC18: =COUNTIF($C18:$AA18,"OK")
A19: Beverage Temprature After Warmer | B19: Startup & 4 hrs | C19: – | D19: – | E19: – | F19: – | I19: – | J19: – | K19: – | L19: – | M19: – | N19: – | O19: – | P19: – | Q19: – | R19: – | S19: – | T19: – | Y19: – | Z19: – | AB19: =COUNTA($C19:$AA19) | AC19: =COUNTIF($C19:$AA19,"OK")
A20: Condensation on Bottle | B20: Startup & 2 hrs | C20: – | D20: – | E20: – | F20: – | I20: – | J20: – | K20: – | L20: – | M20: – | N20: – | O20: – | P20: – | Q20: – | R20: – | S20: – | T20: – | Y20: – | Z20: – | AB20: =COUNTA($C20:$AA20) | AC20: =COUNTIF($C20:$AA20,"OK")
A21: Label Alignment | B21: Startup & Every 30 Min | C21: OK | D21: OK | E21: OK | F21: OK | I21: OK | J21: OK | K21: OK | L21: OK | M21: OK | N21: OK | O21: OK | P21: OK | Q21: OK | R21: OK | S21: OK | T21: OK | Y21: OK | Z21: OK | AB21: =COUNTA($C21:$AA21) | AC21: =COUNTIF($C21:$AA21,"OK")
A22: Glue Application | B22: Startup & Every 30 Min | C22: OK | D22: OK | E22: OK | F22: OK | I22: OK | J22: OK | K22: OK | L22: OK | M22: OK | N22: OK | O22: OK | P22: OK | Q22: OK | R22: OK | S22: OK | T22: OK | Y22: OK | Z22: OK | AB22: =COUNTA($C22:$AA22) | AC22: =COUNTIF($C22:$AA22,"OK")
A23: Primary Coding | B23: Startup & Every 30 Min | C23: OK | D23: OK | E23: OK | F23: OK | I23: OK | J23: OK | K23: OK | L23: OK | M23: OK | N23: OK | O23: OK | P23: OK | Q23: OK | R23: OK | S23: OK | T23: OK | Y23: OK | Z23: OK | AB23: =COUNTA($C23:$AA23) | AC23: =COUNTIF($C23:$AA23,"OK")
A24: Shrink packing Quality | B24: Startup & Every Hour | C24: OK | D24: OK | E24: OK | F24: OK | I24: OK | J24: OK | K24: OK | L24: OK | M24: OK | N24: OK | O24: OK | P24: OK | Q24: OK | R24: OK | S24: OK | T24: OK | Y24: OK | Z24: OK | AB24: =COUNTA($C24:$AA24) | AC24: =COUNTIF($C24:$AA24,"OK")
A25: Torque | B25: All Capper Heads Start Up & Every 2 Hours | AB25: =COUNTA($C25:$AA25) | AC25: =COUNTIF($C25:$AA25,"OK")
A26: Closure Lot No. | AB26: =COUNTA($C26:$AA26) | AC26: =COUNTIF($C26:$AA26,"OK")
A27: Label Lot No. | AB27: =COUNTA($C27:$AA27) | AC27: =COUNTIF($C27:$AA27,"OK")
A28: Preform Lot No. | AB28: =COUNTA($C28:$AA28) | AC28: =COUNTIF($C28:$AA28,"OK")
A29: Parameters filled in this column | B29: (live count) | C29: =COUNTA(C11:C28) | D29: =COUNTA(D11:D28) | E29: =COUNTA(E11:E28) | F29: =COUNTA(F11:F28) | G29: =COUNTA(G11:G28) | H29: =COUNTA(H11:H28) | I29: =COUNTA(I11:I28) | J29: =COUNTA(J11:J28) | ... AA29: =COUNTA(AA11:AA28) | AB29: =SUM(C29:AA29) | AG29: =SUM(AG11:AG28) | AH29: =SUM(AH11:AH28)
A31: Annotations written on the form
A32: Where | B32: What the chemist wrote
A33: 05:00 - 06:30 columns | B33: Vertical notes: "Filler Stop" and "15 min", bracketed across these columns - no readings logged for 05:00-06:30. Small markers "1" and "2" are written at the head of the 05:00 and 06:30 columns.
A34: 10:00 - 10:30 columns | B34: No readings logged; no explanatory note written on the form.
A36: Remark (as written on form) | B36: (left blank on the form)
A37: QC Chemist | B37: Pammee Singh | E37: QC Manager | I37: (initialled)
A38: Note below the table | B38: Handwritten below the table: "MC2 Original 250 ml Pyramid / 3500 previously washed bottle / were run on the production line / time 7:00 Pm start ..." (final line runs off the bottom edge of the photograph)
A40: Notes on this sheet
A41: • Blank cell = left blank on the paper form. – = a dash was written (the test was not due at that interval). OK = written as OK.
A42: • The 24-hour row under the printed times is our addition; the form prints 12-hour times with no am/pm marker.
A43: • Entries / OK count / Min / Max / Average / pair columns are live formulas over the time columns to their left - correct any reading and they re-derive.
A44: • “:00/:30 pairs” counts the paired readings actually written; “Pairs differing” counts pairs whose two halves are not identical. That is the accuracy check for this form, which carries no arithmetic column.
A45: • Cells carrying a red figure have a comment attached explaining the ambiguity or source anomaly.
...

Sheet Torque 17-08-2026
A1: ASIAN LAKTO INDUSTRIES LTD
A2: TORQUE TESTING REPORT (HYMECH LINE)
A3: transcribed from Photo 4 (PDF page 4)
A5: DATE | B5: 17/08/26 | E5: SHIFT | F5: Day
A6: PRODUCT | B6: MC2 Original 250 ml | E6: CHEMIST NAME | F6: Pammee
A7: CAP MAKE | B7: MD
A8: ="Acceptance band used by the checks below: "&TEXT(SPEC_LOW,"0.0")&" to "&TEXT(SPEC_HIGH,"0.0")&" lb-in (editable on the Index & Checks sheet - the form itself prints no limits)"
C9: CAPPER HEAD
A10: TIME | B10: Entry | C10: 1 | D10: 2 | E10: 3 | F10: 4 | G10: 5 | H10: 6 | I10: 7 | J10: 8 | K10: 9 | L10: 10 | M10: 11 | N10: 12 | O10: 13 | P10: 14 | Q10: 15 | R10: REMARK
A11: 09:00 | B11: Reading (lb-in) | S11: not recorded
B12: Re-test / Result
A13: 11:00 | B13: Reading (lb-in) | C13: 25.8 | D13: 10.1 | E13: 27.7 | F13: 15.9 | G13: 10.1 | H13: 10.2 | I13: 16.7 | J13: 10 | K13: 12.7 | L13: 6 | M13: 15.9 | N13: 10.3 | O13: 25.4 | P13: No open | Q13: 10 | S13: =COUNT($C13:$Q13)&" numeric"
B14: Re-test / Result | C14: 12.3 | D14: OK | E14: 17.5 | F14: OK | G14: OK | H14: OK | I14: OK | J14: OK | K14: OK | L14: 10.8 | M14: OK | N14: OK | O14: 11.7 | P14: 16 | Q14: OK
A15: 01:00 | B15: Reading (lb-in) | C15: 10 | D15: 11.8 | E15: 14 | F15: 20.5 | G15: 13.8 | H15: 9.9 | I15: 10.7 | J15: 25.4 | K15: 13.8 | L15: 7.6 | M15: 14.3 | N15: 14.2 | O15: 25.1 | P15: 26.3 | Q15: 13 | S15: =COUNT($C15:$Q15)&" numeric"
B16: Re-test / Result | C16: OK | D16: OK | E16: OK | F16: 15.5 | G16: OK | H16: OK | I16: OK | J16: 16 | K16: OK | L16: 10.5 | M16: OK | N16: OK | O16: 15 | P16: 16.3 | Q16: OK
A17: 03:00 | B17: Reading (lb-in) | S17: not recorded
B18: Re-test / Result
A19: 05:00 | B19: Reading (lb-in) | S19: not recorded
B20: Re-test / Result
A21: 07:00 | B21: Reading (lb-in) | S21: not recorded
B22: Re-test / Result
A24: Verification - every cell below is a live formula
A25: TIME | B25: Check | C25: 1 | D25: 2 | E25: 3 | F25: 4 | G25: 5 | H25: 6 | I25: 7 | J25: 8 | K25: 9 | L25: 10 | M25: 11 | N25: 12 | O25: 13 | P25: 14 | Q25: 15 | R25: Count
A26: 11:00 | B26: Ringed on the form (as transcribed) | C26: Y | E26: Y | L26: Y | O26: Y | P26: Y | R26: =COUNTIF($C26:$Q26,"Y") | S26: rejected by the chemist
B27: Outside band (formula) | C27: =IF(NOT(ISNUMBER(C13)),"n/a",IF(OR(C13<SPEC_LOW,C13>SPEC_HIGH),"OUT","in")) | D27: =IF(NOT(ISNUMBER(D13)),"n/a",IF(OR(D13<SPEC_LOW,D13>SPEC_HIGH),"OUT","in")) | E27: =IF(NOT(ISNUMBER(E13)),"n/a",IF(OR(E13<SPEC_LOW,E13>SPEC_HIGH),"OUT","in")) | F27: =IF(NOT(ISNUMBER(F13)),"n/a",IF(OR(F13<SPEC_LOW,F13>SPEC_HIGH),"OUT","in")) | G27: =IF(NOT(ISNUMBER(G13)),"n/a",IF(OR(G13<SPEC_LOW,G13>SPEC_HIGH),"OUT","in")) | H27: =IF(NOT(ISNUMBER(H13)),"n/a",IF(OR(H13<SPEC_LOW,H13>SPEC_HIGH),"OUT","in")) | I27: =IF(NOT(ISNUMBER(I13)),"n/a",IF(OR(I13<SPEC_LOW,I13>SPEC_HIGH),"OUT","in")) | J27: =IF(NOT(ISNUMBER(J13)),"n/a",IF(OR(J13<SPEC_LOW,J13>SPEC_HIGH),"OUT","in")) | ... Q27: =IF(NOT(ISNUMBER(Q13)),"n/a",IF(OR(Q13<SPEC_LOW,Q13>SPEC_HIGH),"OUT","in")) | R27: =COUNTIF($C27:$Q27,"OUT") | S27: flagged by the formula
B28: Formula agrees with the form? | C28: =IF(NOT(ISNUMBER(C13)),"n/a",IF((C26="Y")=OR(C13<SPEC_LOW,C13>SPEC_HIGH),"agrees","MISMATCH")) | D28: =IF(NOT(ISNUMBER(D13)),"n/a",IF((D26="Y")=OR(D13<SPEC_LOW,D13>SPEC_HIGH),"agrees","MISMATCH")) | E28: =IF(NOT(ISNUMBER(E13)),"n/a",IF((E26="Y")=OR(E13<SPEC_LOW,E13>SPEC_HIGH),"agrees","MISMATCH")) | F28: =IF(NOT(ISNUMBER(F13)),"n/a",IF((F26="Y")=OR(F13<SPEC_LOW,F13>SPEC_HIGH),"agrees","MISMATCH")) | G28: =IF(NOT(ISNUMBER(G13)),"n/a",IF((G26="Y")=OR(G13<SPEC_LOW,G13>SPEC_HIGH),"agrees","MISMATCH")) | H28: =IF(NOT(ISNUMBER(H13)),"n/a",IF((H26="Y")=OR(H13<SPEC_LOW,H13>SPEC_HIGH),"agrees","MISMATCH")) | I28: =IF(NOT(ISNUMBER(I13)),"n/a",IF((I26="Y")=OR(I13<SPEC_LOW,I13>SPEC_HIGH),"agrees","MISMATCH")) | J28: =IF(NOT(ISNUMBER(J13)),"n/a",IF((J26="Y")=OR(J13<SPEC_LOW,J13>SPEC_HIGH),"agrees","MISMATCH")) | ... Q28: =IF(NOT(ISNUMBER(Q13)),"n/a",IF((Q26="Y")=OR(Q13<SPEC_LOW,Q13>SPEC_HIGH),"agrees","MISMATCH")) | R28: =COUNTIF($C28:$Q28,"MISMATCH") | S28: must be 0
A29: 01:00 | B29: Ringed on the form (as transcribed) | F29: Y | J29: Y | L29: Y | O29: Y | P29: Y | R29: =COUNTIF($C29:$Q29,"Y") | S29: rejected by the chemist
B30: Outside band (formula) | C30: =IF(NOT(ISNUMBER(C15)),"n/a",IF(OR(C15<SPEC_LOW,C15>SPEC_HIGH),"OUT","in")) | D30: =IF(NOT(ISNUMBER(D15)),"n/a",IF(OR(D15<SPEC_LOW,D15>SPEC_HIGH),"OUT","in")) | E30: =IF(NOT(ISNUMBER(E15)),"n/a",IF(OR(E15<SPEC_LOW,E15>SPEC_HIGH),"OUT","in")) | F30: =IF(NOT(ISNUMBER(F15)),"n/a",IF(OR(F15<SPEC_LOW,F15>SPEC_HIGH),"OUT","in")) | G30: =IF(NOT(ISNUMBER(G15)),"n/a",IF(OR(G15<SPEC_LOW,G15>SPEC_HIGH),"OUT","in")) | H30: =IF(NOT(ISNUMBER(H15)),"n/a",IF(OR(H15<SPEC_LOW,H15>SPEC_HIGH),"OUT","in")) | I30: =IF(NOT(ISNUMBER(I15)),"n/a",IF(OR(I15<SPEC_LOW,I15>SPEC_HIGH),"OUT","in")) | J30: =IF(NOT(ISNUMBER(J15)),"n/a",IF(OR(J15<SPEC_LOW,J15>SPEC_HIGH),"OUT","in")) | ... Q30: =IF(NOT(ISNUMBER(Q15)),"n/a",IF(OR(Q15<SPEC_LOW,Q15>SPEC_HIGH),"OUT","in")) | R30: =COUNTIF($C30:$Q30,"OUT") | S30: flagged by the formula
B31: Formula agrees with the form? | C31: =IF(NOT(ISNUMBER(C15)),"n/a",IF((C29="Y")=OR(C15<SPEC_LOW,C15>SPEC_HIGH),"agrees","MISMATCH")) | D31: =IF(NOT(ISNUMBER(D15)),"n/a",IF((D29="Y")=OR(D15<SPEC_LOW,D15>SPEC_HIGH),"agrees","MISMATCH")) | E31: =IF(NOT(ISNUMBER(E15)),"n/a",IF((E29="Y")=OR(E15<SPEC_LOW,E15>SPEC_HIGH),"agrees","MISMATCH")) | F31: =IF(NOT(ISNUMBER(F15)),"n/a",IF((F29="Y")=OR(F15<SPEC_LOW,F15>SPEC_HIGH),"agrees","MISMATCH")) | G31: =IF(NOT(ISNUMBER(G15)),"n/a",IF((G29="Y")=OR(G15<SPEC_LOW,G15>SPEC_HIGH),"agrees","MISMATCH")) | H31: =IF(NOT(ISNUMBER(H15)),"n/a",IF((H29="Y")=OR(H15<SPEC_LOW,H15>SPEC_HIGH),"agrees","MISMATCH")) | I31: =IF(NOT(ISNUMBER(I15)),"n/a",IF((I29="Y")=OR(I15<SPEC_LOW,I15>SPEC_HIGH),"agrees","MISMATCH")) | J31: =IF(NOT(ISNUMBER(J15)),"n/a",IF((J29="Y")=OR(J15<SPEC_LOW,J15>SPEC_HIGH),"agrees","MISMATCH")) | ... Q31: =IF(NOT(ISNUMBER(Q15)),"n/a",IF((Q29="Y")=OR(Q15<SPEC_LOW,Q15>SPEC_HIGH),"agrees","MISMATCH")) | R31: =COUNTIF($C31:$Q31,"MISMATCH") | S31: must be 0
A33: Statistics per test round - live formulas
A34: Test round | B34: Numeric readings | C34: Minimum | D34: Maximum | E34: Average | F34: Rejected (ringed) | G34: Re-tests written | H34: Re-tests inside band
A35: 11:00 | B35: =COUNT($C13:$Q13) | C35: =MIN($C13:$Q13) | D35: =MAX($C13:$Q13) | E35: =AVERAGE($C13:$Q13) | F35: =COUNTIF($C26:$Q26,"Y") | G35: =COUNT($C14:$Q14) | H35: =SUMPRODUCT(($C14:$Q14<>"")*(ISNUMBER($C14:$Q14))*($C14:$Q14>=SPEC_LOW)*($C14:$Q14<=SPEC_HIGH))
A36: 01:00 | B36: =COUNT($C15:$Q15) | C36: =MIN($C15:$Q15) | D36: =MAX($C15:$Q15) | E36: =AVERAGE($C15:$Q15) | F36: =COUNTIF($C29:$Q29,"Y") | G36: =COUNT($C16:$Q16) | H36: =SUMPRODUCT(($C16:$Q16<>"")*(ISNUMBER($C16:$Q16))*($C16:$Q16>=SPEC_LOW)*($C16:$Q16<=SPEC_HIGH))
A37: TOTAL | B37: =SUM(B35,B36) | C37: =MIN(C35,C36) | D37: =MAX(D35,D36) | E37: =AVERAGE($C13:$Q13,$C15:$Q15) | F37: =SUM(F35,F36) | G37: =SUM(G35,G36) | H37: =SUM(H35,H36)
A39: Notes on this sheet
A40: • The paper form prints six test rounds (09:00, 11:00, 01:00, 03:00, 05:00, 07:00). Only 11:00 and 01:00 were filled in; the greyed rounds were left blank and are reproduced empty rather than dropped.
A41: • A reading the chemist ringed on the form was rejected, and the re-test he then wrote underneath appears on the 'Re-test / Result' line. 'OK' on that line means the first reading was accepted.
A42: • The form prints no acceptance limits. The band on the Index sheet is the one consistent with every ringing decision made across both sheets - see that sheet for how it was derived. Change the two cells and every check here re-derives.
A43: • 'Formula agrees with the form?' compares the band test against the chemist's own ringing for each head. Any MISMATCH means a digit was probably misread - the count must be 0.
A44: • Cells carrying a red figure have a comment attached explaining the ambiguity.
...

Sheet Torque 20-08-2026
A1: ASIAN LAKTO INDUSTRIES LTD
A2: TORQUE TESTING REPORT (HYMECH LINE)
A3: transcribed from Photo 2 (PDF page 2)
A5: DATE | B5: 20/08/26 | E5: SHIFT | F5: Day
A6: PRODUCT | B6: MC2 Original 250 ml | E6: CHEMIST NAME | F6: Pammee Singh
A7: CAP MAKE | B7: MD
A8: ="Acceptance band used by the checks below: "&TEXT(SPEC_LOW,"0.0")&" to "&TEXT(SPEC_HIGH,"0.0")&" lb-in (editable on the Index & Checks sheet - the form itself prints no limits)"
C9: CAPPER HEAD
A10: TIME | B10: Entry | C10: 1 | D10: 2 | E10: 3 | F10: 4 | G10: 5 | H10: 6 | I10: 7 | J10: 8 | K10: 9 | L10: 10 | M10: 11 | N10: 12 | O10: 13 | P10: 14 | Q10: 15 | R10: REMARK
A11: 09:00 | B11: Reading (lb-in) | S11: not recorded
B12: Re-test / Result
A13: 11:00 | B13: Reading (lb-in) | C13: 15 | D13: 13.7 | E13: 15.8 | F13: 24.1 | G13: 11.3 | H13: 7.9 | I13: No open | J13: 9.6 | K13: 12.7 | L13: 35.3 | M13: 17.5 | N13: 14.4 | O13: 26.4 | P13: 21.2 | Q13: 26.3 | S13: =COUNT($C13:$Q13)&" numeric"
B14: Re-test / Result | C14: OK | D14: OK | E14: OK | F14: 15 | G14: OK | I14: 16.6 | J14: OK | K14: OK | L14: 17.5 | M14: OK | N14: OK | O14: 16.3 | P14: 15 | Q14: 17.6
A15: 01:00 | B15: Reading (lb-in) | C15: 17.6 | D15: 14.3 | E15: 14.1 | F15: 16.7 | G15: 9.8 | H15: 13.2 | I15: 17.5 | J15: 14.3 | K15: 18.5 | L15: 22.5 | M15: 20 | N15: 16.2 | O15: 28.8 | P15: 20.3 | Q15: 13 | S15: =COUNT($C15:$Q15)&" numeric"
B16: Re-test / Result | C16: OK | D16: OK | E16: OK | F16: OK | G16: OK | H16: OK | I16: OK | J16: OK | K16: OK | L16: 15.1 | M16: 11.5 | N16: OK | O16: 13 | P16: 14.3 | Q16: OK
A17: 03:00 | B17: Reading (lb-in) | S17: not recorded
B18: Re-test / Result
A19: 05:00 | B19: Reading (lb-in) | S19: not recorded
B20: Re-test / Result
A21: 07:00 | B21: Reading (lb-in) | S21: not recorded
B22: Re-test / Result
A24: Verification - every cell below is a live formula
A25: TIME | B25: Check | C25: 1 | D25: 2 | E25: 3 | F25: 4 | G25: 5 | H25: 6 | I25: 7 | J25: 8 | K25: 9 | L25: 10 | M25: 11 | N25: 12 | O25: 13 | P25: 14 | Q25: 15 | R25: Count
A26: 11:00 | B26: Ringed on the form (as transcribed) | F26: Y | H26: Y | I26: Y | L26: Y | O26: Y | P26: Y | Q26: Y | R26: =COUNTIF($C26:$Q26,"Y") | S26: rejected by the chemist
B27: Outside band (formula) | C27: =IF(NOT(ISNUMBER(C13)),"n/a",IF(OR(C13<SPEC_LOW,C13>SPEC_HIGH),"OUT","in")) | D27: =IF(NOT(ISNUMBER(D13)),"n/a",IF(OR(D13<SPEC_LOW,D13>SPEC_HIGH),"OUT","in")) | E27: =IF(NOT(ISNUMBER(E13)),"n/a",IF(OR(E13<SPEC_LOW,E13>SPEC_HIGH),"OUT","in")) | F27: =IF(NOT(ISNUMBER(F13)),"n/a",IF(OR(F13<SPEC_LOW,F13>SPEC_HIGH),"OUT","in")) | G27: =IF(NOT(ISNUMBER(G13)),"n/a",IF(OR(G13<SPEC_LOW,G13>SPEC_HIGH),"OUT","in")) | H27: =IF(NOT(ISNUMBER(H13)),"n/a",IF(OR(H13<SPEC_LOW,H13>SPEC_HIGH),"OUT","in")) | I27: =IF(NOT(ISNUMBER(I13)),"n/a",IF(OR(I13<SPEC_LOW,I13>SPEC_HIGH),"OUT","in")) | J27: =IF(NOT(ISNUMBER(J13)),"n/a",IF(OR(J13<SPEC_LOW,J13>SPEC_HIGH),"OUT","in")) | ... Q27: =IF(NOT(ISNUMBER(Q13)),"n/a",IF(OR(Q13<SPEC_LOW,Q13>SPEC_HIGH),"OUT","in")) | R27: =COUNTIF($C27:$Q27,"OUT") | S27: flagged by the formula
B28: Formula agrees with the form? | C28: =IF(NOT(ISNUMBER(C13)),"n/a",IF((C26="Y")=OR(C13<SPEC_LOW,C13>SPEC_HIGH),"agrees","MISMATCH")) | D28: =IF(NOT(ISNUMBER(D13)),"n/a",IF((D26="Y")=OR(D13<SPEC_LOW,D13>SPEC_HIGH),"agrees","MISMATCH")) | E28: =IF(NOT(ISNUMBER(E13)),"n/a",IF((E26="Y")=OR(E13<SPEC_LOW,E13>SPEC_HIGH),"agrees","MISMATCH")) | F28: =IF(NOT(ISNUMBER(F13)),"n/a",IF((F26="Y")=OR(F13<SPEC_LOW,F13>SPEC_HIGH),"agrees","MISMATCH")) | G28: =IF(NOT(ISNUMBER(G13)),"n/a",IF((G26="Y")=OR(G13<SPEC_LOW,G13>SPEC_HIGH),"agrees","MISMATCH")) | H28: =IF(NOT(ISNUMBER(H13)),"n/a",IF((H26="Y")=OR(H13<SPEC_LOW,H13>SPEC_HIGH),"agrees","MISMATCH")) | I28: =IF(NOT(ISNUMBER(I13)),"n/a",IF((I26="Y")=OR(I13<SPEC_LOW,I13>SPEC_HIGH),"agrees","MISMATCH")) | J28: =IF(NOT(ISNUMBER(J13)),"n/a",IF((J26="Y")=OR(J13<SPEC_LOW,J13>SPEC_HIGH),"agrees","MISMATCH")) | ... Q28: =IF(NOT(ISNUMBER(Q13)),"n/a",IF((Q26="Y")=OR(Q13<SPEC_LOW,Q13>SPEC_HIGH),"agrees","MISMATCH")) | R28: =COUNTIF($C28:$Q28,"MISMATCH") | S28: must be 0
A29: 01:00 | B29: Ringed on the form (as transcribed) | L29: Y | M29: Y | O29: Y | P29: Y | R29: =COUNTIF($C29:$Q29,"Y") | S29: rejected by the chemist
B30: Outside band (formula) | C30: =IF(NOT(ISNUMBER(C15)),"n/a",IF(OR(C15<SPEC_LOW,C15>SPEC_HIGH),"OUT","in")) | D30: =IF(NOT(ISNUMBER(D15)),"n/a",IF(OR(D15<SPEC_LOW,D15>SPEC_HIGH),"OUT","in")) | E30: =IF(NOT(ISNUMBER(E15)),"n/a",IF(OR(E15<SPEC_LOW,E15>SPEC_HIGH),"OUT","in")) | F30: =IF(NOT(ISNUMBER(F15)),"n/a",IF(OR(F15<SPEC_LOW,F15>SPEC_HIGH),"OUT","in")) | G30: =IF(NOT(ISNUMBER(G15)),"n/a",IF(OR(G15<SPEC_LOW,G15>SPEC_HIGH),"OUT","in")) | H30: =IF(NOT(ISNUMBER(H15)),"n/a",IF(OR(H15<SPEC_LOW,H15>SPEC_HIGH),"OUT","in")) | I30: =IF(NOT(ISNUMBER(I15)),"n/a",IF(OR(I15<SPEC_LOW,I15>SPEC_HIGH),"OUT","in")) | J30: =IF(NOT(ISNUMBER(J15)),"n/a",IF(OR(J15<SPEC_LOW,J15>SPEC_HIGH),"OUT","in")) | ... Q30: =IF(NOT(ISNUMBER(Q15)),"n/a",IF(OR(Q15<SPEC_LOW,Q15>SPEC_HIGH),"OUT","in")) | R30: =COUNTIF($C30:$Q30,"OUT") | S30: flagged by the formula
B31: Formula agrees with the form? | C31: =IF(NOT(ISNUMBER(C15)),"n/a",IF((C29="Y")=OR(C15<SPEC_LOW,C15>SPEC_HIGH),"agrees","MISMATCH")) | D31: =IF(NOT(ISNUMBER(D15)),"n/a",IF((D29="Y")=OR(D15<SPEC_LOW,D15>SPEC_HIGH),"agrees","MISMATCH")) | E31: =IF(NOT(ISNUMBER(E15)),"n/a",IF((E29="Y")=OR(E15<SPEC_LOW,E15>SPEC_HIGH),"agrees","MISMATCH")) | F31: =IF(NOT(ISNUMBER(F15)),"n/a",IF((F29="Y")=OR(F15<SPEC_LOW,F15>SPEC_HIGH),"agrees","MISMATCH")) | G31: =IF(NOT(ISNUMBER(G15)),"n/a",IF((G29="Y")=OR(G15<SPEC_LOW,G15>SPEC_HIGH),"agrees","MISMATCH")) | H31: =IF(NOT(ISNUMBER(H15)),"n/a",IF((H29="Y")=OR(H15<SPEC_LOW,H15>SPEC_HIGH),"agrees","MISMATCH")) | I31: =IF(NOT(ISNUMBER(I15)),"n/a",IF((I29="Y")=OR(I15<SPEC_LOW,I15>SPEC_HIGH),"agrees","MISMATCH")) | J31: =IF(NOT(ISNUMBER(J15)),"n/a",IF((J29="Y")=OR(J15<SPEC_LOW,J15>SPEC_HIGH),"agrees","MISMATCH")) | ... Q31: =IF(NOT(ISNUMBER(Q15)),"n/a",IF((Q29="Y")=OR(Q15<SPEC_LOW,Q15>SPEC_HIGH),"agrees","MISMATCH")) | R31: =COUNTIF($C31:$Q31,"MISMATCH") | S31: must be 0
A33: Statistics per test round - live formulas
A34: Test round | B34: Numeric readings | C34: Minimum | D34: Maximum | E34: Average | F34: Rejected (ringed) | G34: Re-tests written | H34: Re-tests inside band
A35: 11:00 | B35: =COUNT($C13:$Q13) | C35: =MIN($C13:$Q13) | D35: =MAX($C13:$Q13) | E35: =AVERAGE($C13:$Q13) | F35: =COUNTIF($C26:$Q26,"Y") | G35: =COUNT($C14:$Q14) | H35: =SUMPRODUCT(($C14:$Q14<>"")*(ISNUMBER($C14:$Q14))*($C14:$Q14>=SPEC_LOW)*($C14:$Q14<=SPEC_HIGH))
A36: 01:00 | B36: =COUNT($C15:$Q15) | C36: =MIN($C15:$Q15) | D36: =MAX($C15:$Q15) | E36: =AVERAGE($C15:$Q15) | F36: =COUNTIF($C29:$Q29,"Y") | G36: =COUNT($C16:$Q16) | H36: =SUMPRODUCT(($C16:$Q16<>"")*(ISNUMBER($C16:$Q16))*($C16:$Q16>=SPEC_LOW)*($C16:$Q16<=SPEC_HIGH))
A37: TOTAL | B37: =SUM(B35,B36) | C37: =MIN(C35,C36) | D37: =MAX(D35,D36) | E37: =AVERAGE($C13:$Q13,$C15:$Q15) | F37: =SUM(F35,F36) | G37: =SUM(G35,G36) | H37: =SUM(H35,H36)
A39: Notes on this sheet
A40: • The paper form prints six test rounds (09:00, 11:00, 01:00, 03:00, 05:00, 07:00). Only 11:00 and 01:00 were filled in; the greyed rounds were left blank and are reproduced empty rather than dropped.
A41: • A reading the chemist ringed on the form was rejected, and the re-test he then wrote underneath appears on the 'Re-test / Result' line. 'OK' on that line means the first reading was accepted.
A42: • The form prints no acceptance limits. The band on the Index sheet is the one consistent with every ringing decision made across both sheets - see that sheet for how it was derived. Change the two cells and every check here re-derives.
A43: • 'Formula agrees with the form?' compares the band test against the chemist's own ringing for each head. Any MISMATCH means a digit was probably misread - the count must be 0.
A44: • Cells carrying a red figure have a comment attached explaining the ambiguity.
...
